/* History/mksql.py < ../CSV/TMBA0063.csv*/
SELECT `inst_id` INTO @con_inst_id FROM `ControllersInfo` WHERE `sn` = '0063' AND `type_id` = 1; INSERT INTO `InstrumentHist` (`inst_id`, `dt`, `txt`) VALUES (@con_inst_id,'2018-09-10 00:00:00','Built NEW. *USED RECYCLED SEABIRD IMM.'), (@con_inst_id,'2018-09-11 00:00:00','Successfully tested all MET sensor inputs, RF modem, IM data, and GPS (with rooftop antenna), waiting for SIM card.'), (@con_inst_id,'2018-09-12 00:00:00','Installed Iridium SIM card.'), (@con_inst_id,'2018-11-01 00:00:00','Ran Bench current drain test for 3 days with version 2.01, 170530 firmware, RF modem turned off, 13.23mA Average. Downloaded and checked Flash RAM data, which looked good.'), (@con_inst_id,'2018-11-01 00:00:00','Tested internal GPS & Iridium antenna by doing an GPS & XMIT outside, which successfully registered and sent dummy files, plus GPS got position, and Time & Date update.'), (@con_inst_id,'2019-02-08 00:00:00','Tried to use for PI2-19, put outside for testing, started LOG mode, but this system got no iridium calls through overnight. When I tried numerous XMIT commands, the system registered, but always got the message "NO CONNECT MESSAGE RECEIVED". NEEDS TESTING, TROUBLESHOOTING.'), (@con_inst_id,'2019-02-20 00:00:00','Bench tested with rooftop Iridium antenna. Sent the XMIT command, and the system registered and it SUCCESSFULLY got online, and send all 6 dummy blocks without a problem, plus files acknowledged and system hung up, ended call without a problem. Did this XMIT several times. Maybe bad internal Iridium antenna cable, or bad antenna.'), (@con_inst_id,'2019-02-20 00:00:00','REPLACED Iridium Antenna cable. Successfully tested XMITs outside and GPS outside, did 3 XMITs to of 3 successful. It could not register the one time, but did NOT see error messgae of "no connect message received".');
INSERT INTO test_DAW_InstrumentLocation.History (`inst_id`,`dt`,`label_id`,`txt`) VALUES (@con_inst_id,'2018-09-10 00:00:00',1,'Built new');
